[2023-09-04T18:32:51.182+0000] {logging_mixin.py:151} INFO - Changing /opt/***/logs/dag_id=ETL_toll_data/run_id=manual__2023-09-04T18:32:43.910128+00:00/task_id=unzip_data permission to 509
[2023-09-04T18:32:51.191+0000] {logging_mixin.py:151} INFO - Failed to change /opt/***/logs/dag_id=ETL_toll_data/run_id=manual__2023-09-04T18:32:43.910128+00:00/task_id=unzip_data permission to 509: [Errno 1] Operation not permitted: '/opt/***/logs/dag_id=ETL_toll_data/run_id=manual__2023-09-04T18:32:43.910128+00:00/task_id=unzip_data'
[2023-09-04T18:32:51.236+0000] {logging_mixin.py:151} INFO - Changing /opt/***/logs/dag_id=ETL_toll_data/run_id=manual__2023-09-04T18:32:43.910128+00:00/task_id=unzip_data permission to 509
[2023-09-04T18:32:51.237+0000] {logging_mixin.py:151} INFO - Failed to change /opt/***/logs/dag_id=ETL_toll_data/run_id=manual__2023-09-04T18:32:43.910128+00:00/task_id=unzip_data permission to 509: [Errno 1] Operation not permitted: '/opt/***/logs/dag_id=ETL_toll_data/run_id=manual__2023-09-04T18:32:43.910128+00:00/task_id=unzip_data'
[2023-09-04T18:32:51.290+0000] {taskinstance.py:1159} INFO - Dependencies all met for dep_context=non-requeueable deps ti=<TaskInstance: ETL_toll_data.unzip_data manual__2023-09-04T18:32:43.910128+00:00 [queued]>
[2023-09-04T18:32:51.303+0000] {taskinstance.py:1159} INFO - Dependencies all met for dep_context=requeueable deps ti=<TaskInstance: ETL_toll_data.unzip_data manual__2023-09-04T18:32:43.910128+00:00 [queued]>
[2023-09-04T18:32:51.304+0000] {taskinstance.py:1361} INFO - Starting attempt 1 of 2
[2023-09-04T18:32:51.327+0000] {taskinstance.py:1382} INFO - Executing <Task(BashOperator): unzip_data> on 2023-09-04 18:32:43.910128+00:00
[2023-09-04T18:32:51.337+0000] {standard_task_runner.py:57} INFO - Started process 708 to run task
[2023-09-04T18:32:51.343+0000] {standard_task_runner.py:84} INFO - Running: ['***', 'tasks', 'run', 'ETL_toll_data', 'unzip_data', 'manual__2023-09-04T18:32:43.910128+00:00', '--job-id', '40', '--raw', '--subdir', 'DAGS_FOLDER/ETL_toll_data.py', '--cfg-path', '/tmp/tmp2krsmmmo']
[2023-09-04T18:32:51.348+0000] {standard_task_runner.py:85} INFO - Job 40: Subtask unzip_data
[2023-09-04T18:32:51.414+0000] {logging_mixin.py:151} INFO - Changing /opt/***/logs/dag_id=ETL_toll_data/run_id=manual__2023-09-04T18:32:43.910128+00:00/task_id=unzip_data permission to 509
[2023-09-04T18:32:51.415+0000] {logging_mixin.py:151} INFO - Failed to change /opt/***/logs/dag_id=ETL_toll_data/run_id=manual__2023-09-04T18:32:43.910128+00:00/task_id=unzip_data permission to 509: [Errno 1] Operation not permitted: '/opt/***/logs/dag_id=ETL_toll_data/run_id=manual__2023-09-04T18:32:43.910128+00:00/task_id=unzip_data'
[2023-09-04T18:32:51.419+0000] {task_command.py:415} INFO - Running <TaskInstance: ETL_toll_data.unzip_data manual__2023-09-04T18:32:43.910128+00:00 [running]> on host d1a2050adbbc
[2023-09-04T18:32:51.528+0000] {taskinstance.py:1660} INFO - Exporting env vars: AIRFLOW_CTX_DAG_EMAIL='priyanshud310@gmail.com' AIRFLOW_CTX_DAG_OWNER='Priyanshu Dhiman' AIRFLOW_CTX_DAG_ID='ETL_toll_data' AIRFLOW_CTX_TASK_ID='unzip_data' AIRFLOW_CTX_EXECUTION_DATE='2023-09-04T18:32:43.910128+00:00' AIRFLOW_CTX_TRY_NUMBER='1' AIRFLOW_CTX_DAG_RUN_ID='manual__2023-09-04T18:32:43.910128+00:00'
[2023-09-04T18:32:51.553+0000] {subprocess.py:63} INFO - Tmp dir root location: /tmp
[2023-09-04T18:32:51.555+0000] {subprocess.py:75} INFO - Running command: ['/bin/bash', '-c', 'tar -xzf D:/docker-***/dags/finalassignment/tolldata.tgz']
[2023-09-04T18:32:51.577+0000] {subprocess.py:86} INFO - Output:
[2023-09-04T18:33:22.590+0000] {subprocess.py:93} INFO - tar (child): Cannot connect to D: resolve failed
[2023-09-04T18:33:22.655+0000] {subprocess.py:93} INFO - 
[2023-09-04T18:33:22.692+0000] {subprocess.py:93} INFO - gzip: stdin: unexpected end of file
[2023-09-04T18:33:22.699+0000] {subprocess.py:93} INFO - tar: Child returned status 128
[2023-09-04T18:33:22.717+0000] {subprocess.py:93} INFO - tar: Error is not recoverable: exiting now
[2023-09-04T18:33:22.721+0000] {subprocess.py:97} INFO - Command exited with return code 2
[2023-09-04T18:33:25.363+0000] {taskinstance.py:1943} ERROR - Task failed with exception
Traceback (most recent call last):
  File "/home/airflow/.local/lib/python3.8/site-packages/airflow/operators/bash.py", line 210, in execute
    raise AirflowException(
airflow.exceptions.AirflowException: Bash command failed. The command returned a non-zero exit code 2.
[2023-09-04T18:33:25.456+0000] {taskinstance.py:1400} INFO - Marking task as UP_FOR_RETRY. dag_id=ETL_toll_data, task_id=unzip_data, execution_date=20230904T183243, start_date=20230904T183251, end_date=20230904T183325
[2023-09-04T18:33:25.624+0000] {warnings.py:109} WARNING - /home/***/.local/lib/python3.8/site-packages/***/utils/email.py:154: RemovedInAirflow3Warning: Fetching SMTP credentials from configuration variables will be deprecated in a future release. Please set credentials using a connection instead.
  send_mime_email(e_from=mail_from, e_to=recipients, mime_msg=msg, conn_id=conn_id, dryrun=dryrun)

[2023-09-04T18:33:25.629+0000] {configuration.py:1064} WARNING - section/key [smtp/smtp_user] not found in config
[2023-09-04T18:33:25.631+0000] {email.py:270} INFO - Email alerting: attempt 1
[2023-09-04T18:33:26.466+0000] {configuration.py:1064} WARNING - section/key [smtp/smtp_user] not found in config
[2023-09-04T18:33:26.485+0000] {email.py:270} INFO - Email alerting: attempt 1
[2023-09-04T18:33:26.493+0000] {taskinstance.py:2013} ERROR - Failed to send email to: ['priyanshud310@gmail.com']
Traceback (most recent call last):
  File "/home/airflow/.local/lib/python3.8/site-packages/airflow/models/taskinstance.py", line 1518, in _run_raw_task
    self._execute_task_with_callbacks(context, test_mode, session=session)
  File "/home/airflow/.local/lib/python3.8/site-packages/airflow/models/taskinstance.py", line 1679, in _execute_task_with_callbacks
    result = self._execute_task(context, task_orig)
  File "/home/airflow/.local/lib/python3.8/site-packages/airflow/models/taskinstance.py", line 1750, in _execute_task
    result = execute_callable(context=context)
  File "/home/airflow/.local/lib/python3.8/site-packages/airflow/operators/bash.py", line 210, in execute
    raise AirflowException(
airflow.exceptions.AirflowException: Bash command failed. The command returned a non-zero exit code 2.

During handling of the above exception, another exception occurred:

Traceback (most recent call last):
  File "/home/airflow/.local/lib/python3.8/site-packages/airflow/models/taskinstance.py", line 2426, in email_alert
    send_email(task.email, subject, html_content)
  File "/home/airflow/.local/lib/python3.8/site-packages/airflow/utils/email.py", line 80, in send_email
    return backend(
  File "/home/airflow/.local/lib/python3.8/site-packages/airflow/utils/email.py", line 154, in send_email_smtp
    send_mime_email(e_from=mail_from, e_to=recipients, mime_msg=msg, conn_id=conn_id, dryrun=dryrun)
  File "/home/airflow/.local/lib/python3.8/site-packages/airflow/utils/email.py", line 272, in send_mime_email
    smtp_conn = _get_smtp_connection(smtp_host, smtp_port, smtp_timeout, smtp_ssl)
  File "/home/airflow/.local/lib/python3.8/site-packages/airflow/utils/email.py", line 317, in _get_smtp_connection
    return smtplib.SMTP(host=host, port=port, timeout=timeout)
  File "/usr/local/lib/python3.8/smtplib.py", line 255, in __init__
    (code, msg) = self.connect(host, port)
  File "/usr/local/lib/python3.8/smtplib.py", line 339, in connect
    self.sock = self._get_socket(host, port, self.timeout)
  File "/usr/local/lib/python3.8/smtplib.py", line 310, in _get_socket
    return socket.create_connection((host, port), timeout,
  File "/usr/local/lib/python3.8/socket.py", line 808, in create_connection
    raise err
  File "/usr/local/lib/python3.8/socket.py", line 796, in create_connection
    sock.connect(sa)
OSError: [Errno 99] Cannot assign requested address

During handling of the above exception, another exception occurred:

Traceback (most recent call last):
  File "/home/airflow/.local/lib/python3.8/site-packages/airflow/models/taskinstance.py", line 2011, in handle_failure
    self.email_alert(error, task)
  File "/home/airflow/.local/lib/python3.8/site-packages/airflow/models/taskinstance.py", line 2428, in email_alert
    send_email(task.email, subject, html_content_err)
  File "/home/airflow/.local/lib/python3.8/site-packages/airflow/utils/email.py", line 80, in send_email
    return backend(
  File "/home/airflow/.local/lib/python3.8/site-packages/airflow/utils/email.py", line 154, in send_email_smtp
    send_mime_email(e_from=mail_from, e_to=recipients, mime_msg=msg, conn_id=conn_id, dryrun=dryrun)
  File "/home/airflow/.local/lib/python3.8/site-packages/airflow/utils/email.py", line 272, in send_mime_email
    smtp_conn = _get_smtp_connection(smtp_host, smtp_port, smtp_timeout, smtp_ssl)
  File "/home/airflow/.local/lib/python3.8/site-packages/airflow/utils/email.py", line 317, in _get_smtp_connection
    return smtplib.SMTP(host=host, port=port, timeout=timeout)
  File "/usr/local/lib/python3.8/smtplib.py", line 255, in __init__
    (code, msg) = self.connect(host, port)
  File "/usr/local/lib/python3.8/smtplib.py", line 339, in connect
    self.sock = self._get_socket(host, port, self.timeout)
  File "/usr/local/lib/python3.8/smtplib.py", line 310, in _get_socket
    return socket.create_connection((host, port), timeout,
  File "/usr/local/lib/python3.8/socket.py", line 808, in create_connection
    raise err
  File "/usr/local/lib/python3.8/socket.py", line 796, in create_connection
    sock.connect(sa)
OSError: [Errno 99] Cannot assign requested address
[2023-09-04T18:33:26.655+0000] {standard_task_runner.py:104} ERROR - Failed to execute job 40 for task unzip_data (Bash command failed. The command returned a non-zero exit code 2.; 708)
[2023-09-04T18:33:26.709+0000] {local_task_job_runner.py:228} INFO - Task exited with return code 1
[2023-09-04T18:33:26.897+0000] {taskinstance.py:2784} INFO - 0 downstream tasks scheduled from follow-on schedule check
